Workbook
Name INDICE: #REF!

Sheet Monitoramento Acumulado Geral
A1: EMPRESA JÚNIOR | B1: MÊS | C1: MÊS KEY | D1: PROJETOS 2017 | E1: FATURAMENTO 2017 | F1: PROJETOS ACUMULADOS 2017 | G1: FATURAMENTO ACUMULADO 2017 | H1: PROJETOS 2018 | I1: FATURAMENTO 2018 | J1: PROJETOS ACUMULADOS 2018 | K1: FATURAMENTO ACUMULADO 2018 | L1: PROJETOS 2019 | M1: FATURAMENTO 2019 | N1: PROJETOS ACUMULADO 2019 | O1: FATURAMENTO ACUMULADO 2019 | P1: PROJETOS 2020 | Q1: FATURAMENTO 2020 | R1: PROJETOS ACUMULADO 2020 | S1: FATURAMENTO ACUMULADO 2020
A2: AJTAL - ASSOCIAÇÃO JÚNIOR DE TECNÓLOGOS EM ALIMENTOS CONSULTORIA E PROJETOS | P2: 0 | Q2: 0 | R2: 0 | S2: 0
A3: AJTAL - ASSOCIAÇÃO JÚNIOR DE TECNÓLOGOS EM ALIMENTOS CONSULTORIA E PROJETOS | P3: 0 | Q3: 0 | R3: 0 | S3: 0
A4: AJTAL - ASSOCIAÇÃO JÚNIOR DE TECNÓLOGOS EM ALIMENTOS CONSULTORIA E PROJETOS | P4: 0 | Q4: 0 | R4: 0 | S4: 0
A5: AJTAL - ASSOCIAÇÃO JÚNIOR DE TECNÓLOGOS EM ALIMENTOS CONSULTORIA E PROJETOS | P5: 0 | Q5: 0 | R5: 0 | S5: 0
A6: AJTAL - ASSOCIAÇÃO JÚNIOR DE TECNÓLOGOS EM ALIMENTOS CONSULTORIA E PROJETOS | P6: 0 | Q6: 0 | R6: 0 | S6: 0
A7: AJTAL - ASSOCIAÇÃO JÚNIOR DE TECNÓLOGOS EM ALIMENTOS CONSULTORIA E PROJETOS | P7: 0 | Q7: 0 | R7: 0 | S7: 0
A8: AJTAL - ASSOCIAÇÃO JÚNIOR DE TECNÓLOGOS EM ALIMENTOS CONSULTORIA E PROJETOS | P8: 0 | Q8: 0 | R8: 0 | S8: 0
A9: AJTAL - ASSOCIAÇÃO JÚNIOR DE TECNÓLOGOS EM ALIMENTOS CONSULTORIA E PROJETOS | P9: 1 | Q9: 240 | R9: 9 | S9: 1320
A10: AJTAL - ASSOCIAÇÃO JÚNIOR DE TECNÓLOGOS EM ALIMENTOS CONSULTORIA E PROJETOS | P10: 0 | Q10: 0 | R10: 9 | S10: 1320
A11: AJTAL - ASSOCIAÇÃO JÚNIOR DE TECNÓLOGOS EM ALIMENTOS CONSULTORIA E PROJETOS | P11: 0 | Q11: 0 | R11: 9 | S11: 1320
A12: AJTAL - ASSOCIAÇÃO JÚNIOR DE TECNÓLOGOS EM ALIMENTOS CONSULTORIA E PROJETOS
A13: AJTAL - ASSOCIAÇÃO JÚNIOR DE TECNÓLOGOS EM ALIMENTOS CONSULTORIA E PROJETOS
A14: Atena Consultoria Jr. | B14: Janeiro | C14: 1 | D14: 0 | E14: 0 | F14: =D14 -> 0 | G14: =E14 -> 0 | H14: 0 | I14: 0 | J14: =H14 -> 0 | K14: =I14 -> 0 | L14: 2 | M14: 4050 | N14: =L14 -> 2 | O14: =M14 -> 4050 | P14: 4 | Q14: 1892 | R14: 4 | S14: 1892
A15: Atena Consultoria Jr. | B15: Fevereiro | C15: 2 | D15: 0 | E15: 0 | F15: =F14+D15 -> 0 | G15: =G14+E15 -> 0 | H15: 0 | I15: 0 | J15: =J14+H15 -> 0 | K15: =K14+I15 -> 0 | L15: 1 | M15: 400 | N15: =N14+L15 -> 3 | O15: =O14+M15 -> 4450 | P15: 5 | Q15: 5605 | R15: 9 | S15: 7497
A16: Atena Consultoria Jr. | B16: Março | C16: 3 | D16: 0 | E16: 0 | F16: =F15+D16 -> 0 | G16: =G15+E16 -> 0 | H16: 0 | I16: 0 | J16: =J15+H16 -> 0 | K16: =K15+I16 -> 0 | L16: 0 | M16: 0 | N16: =N15+L16 -> 3 | O16: =O15+M16 -> 4450 | P16: 0 | Q16: 0 | R16: 9 | S16: 7497
A17: Atena Consultoria Jr. | B17: Abril | C17: 4 | D17: 0 | E17: 0 | F17: =F16+D17 -> 0 | G17: =G16+E17 -> 0 | H17: 0 | I17: 0 | J17: =J16+H17 -> 0 | K17: =K16+I17 -> 0 | L17: 1 | M17: 180 | N17: =N16+L17 -> 4 | O17: =O16+M17 -> 4630 | P17: 0 | Q17: 0 | R17: 9 | S17: 7497
A18: Atena Consultoria Jr. | B18: Maio | C18: 5 | D18: 0 | E18: 0 | F18: =F17+D18 -> 0 | G18: =G17+E18 -> 0 | H18: 0 | I18: 0 | J18: =J17+H18 -> 0 | K18: =K17+I18 -> 0 | L18: 2 | M18: 1890 | N18: =N17+L18 -> 6 | O18: =O17+M18 -> 6520 | P18: 0 | Q18: 0 | R18: 9 | S18: 7497
A19: Atena Consultoria Jr. | B19: Junho | C19: 6 | D19: 0 | E19: 0 | F19: =F18+D19 -> 0 | G19: =G18+E19 -> 0 | H19: 0 | I19: 0 | J19: =J18+H19 -> 0 | K19: =K18+I19 -> 0 | L19: 2 | M19: 1656 | N19: =N18+L19 -> 8 | O19: =O18+M19 -> 8176 | P19: 1 | Q19: 2220 | R19: 10 | S19: 9717 | U19: Dados de anos anteriores estão ocultos à partir da Coluna B.
A20: Atena Consultoria Jr. | B20: Julho | C20: 7 | D20: 0 | E20: 0 | F20: =F19+D20 -> 0 | G20: =G19+E20 -> 0 | H20: 1 | I20: 220 | J20: =J19+H20 -> 1 | K20: =K19+I20 -> 220 | L20: 0 | M20: 0 | N20: =N19+L20 -> 8 | O20: =O19+M20 -> 8176 | P20: 2 | Q20: 1800 | R20: 12 | S20: 11517
A21: Atena Consultoria Jr. | B21: Agosto | C21: 8 | D21: 0 | E21: 0 | F21: =F20+D21 -> 0 | G21: =G20+E21 -> 0 | H21: 1 | I21: 1119.62 | J21: =J20+H21 -> 2 | K21: =K20+I21 -> 1339.62 | L21: 1 | M21: 310 | N21: =N20+L21 -> 9 | O21: =O20+M21 -> 8486 | P21: 0 | Q21: 0 | R21: 12 | S21: 11517
A22: Atena Consultoria Jr. | B22: Setembro | C22: 9 | D22: 0 | E22: 0 | F22: =F21+D22 -> 0 | G22: =G21+E22 -> 0 | H22: 0 | I22: 0 | J22: =J21+H22 -> 2 | K22: =K21+I22 -> 1339.62 | L22: 2 | M22: 1490 | N22: =N21+L22 -> 11 | O22: =O21+M22 -> 9976 | P22: 0 | Q22: 0 | R22: 12 | S22: 11517
A23: Atena Consultoria Jr. | B23: Outubro | C23: 10 | D23: 0 | E23: 0 | F23: =F22+D23 -> 0 | G23: =G22+E23 -> 0 | H23: 1 | I23: 420 | J23: =J22+H23 -> 3 | K23: =K22+I23 -> 1759.62 | L23: 2 | M23: 1180 | N23: =N22+L23 -> 13 | O23: =O22+M23 -> 11156 | P23: 0 | Q23: 0 | R23: 12 | S23: 11517
A24: Atena Consultoria Jr. | B24: Novembro | C24: 11 | D24: 0 | E24: 0 | F24: =F23+D24 -> 0 | G24: =G23+E24 -> 0 | H24: 1 | I24: 1940 | J24: =J23+H24 -> 4 | K24: =K23+I24 -> 3699.62 | L24: 3 | M24: 2740 | N24: =N23+L24 -> 16 | O24: =O23+M24 -> 13896 | Q24: 0
A25: Atena Consultoria Jr. | B25: Dezembro | C25: 12 | D25: 0 | E25: 0 | F25: =F24+D25 -> 0 | G25: =G24+E25 -> 0 | H25: 0 | I25: 0 | J25: =J24+H25 -> 4 | K25: =K24+I25 -> 3699.62 | L25: 1 | M25: 1500 | N25: =N24+L25 -> 17 | O25: =O24+M25 -> 15396 | Q25: 0
A26: Atlântica Consultoria Internacional | B26: Janeiro | C26: 1 | D26: 0 | E26: 0 | F26: =D26 -> 0 | G26: =E26 -> 0 | H26: 0 | I26: 0 | J26: =H26 -> 0 | K26: =I26 -> 0 | L26: 0 | M26: 0 | N26: =L26 -> 0 | O26: =M26 -> 0 | P26: 1 | Q26: 244 | R26: 1 | S26: 244
A27: Atlântica Consultoria Internacional | B27: Fevereiro | C27: 2 | D27: 0 | E27: 0 | F27: =F26+D27 -> 0 | G27: =G26+E27 -> 0 | H27: 0 | I27: 0 | J27: =J26+H27 -> 0 | K27: =K26+I27 -> 0 | L27: 0 | M27: 0 | N27: =N26+L27 -> 0 | O27: =O26+M27 -> 0 | P27: 0 | Q27: 0 | R27: 1 | S27: 244
A28: Atlântica Consultoria Internacional | B28: Março | C28: 3 | D28: 0 | E28: 0 | F28: =F27+D28 -> 0 | G28: =G27+E28 -> 0 | H28: 0 | I28: 0 | J28: =J27+H28 -> 0 | K28: =K27+I28 -> 0 | L28: 0 | M28: 0 | N28: =N27+L28 -> 0 | O28: =O27+M28 -> 0 | P28: 0 | Q28: 0 | R28: 1 | S28: 244
A29: Atlântica Consultoria Internacional | B29: Abril | C29: 4 | D29: 0 | E29: 0 | F29: =F28+D29 -> 0 | G29: =G28+E29 -> 0 | H29: 0 | I29: 0 | J29: =J28+H29 -> 0 | K29: =K28+I29 -> 0 | L29: 0 | M29: 0 | N29: =N28+L29 -> 0 | O29: =O28+M29 -> 0 | P29: 1 | Q29: 122 | R29: 2 | S29: 366
A30: Atlântica Consultoria Internacional | B30: Maio | C30: 5 | D30: 0 | E30: 0 | F30: =F29+D30 -> 0 | G30: =G29+E30 -> 0 | H30: 0 | I30: 0 | J30: =J29+H30 -> 0 | K30: =K29+I30 -> 0 | L30: 0 | M30: 0 | N30: =N29+L30 -> 0 | O30: =O29+M30 -> 0 | P30: 0 | Q30: 0 | R30: 2 | S30: 366
A31: Atlântica Consultoria Internacional | B31: Junho | C31: 6 | D31: 0 | E31: 0 | F31: =F30+D31 -> 0 | G31: =G30+E31 -> 0 | H31: 0 | I31: 0 | J31: =J30+H31 -> 0 | K31: =K30+I31 -> 0 | L31: 0 | M31: 0 | N31: =N30+L31 -> 0 | O31: =O30+M31 -> 0 | P31: 2 | Q31: 1 | R31: 4 | S31: 367
A32: Atlântica Consultoria Internacional | B32: Julho | C32: 7 | D32: 0 | E32: 0 | F32: =F31+D32 -> 0 | G32: =G31+E32 -> 0 | H32: 0 | I32: 0 | J32: =J31+H32 -> 0 | K32: =K31+I32 -> 0 | L32: 0 | M32: 0 | N32: =N31+L32 -> 0 | O32: =O31+M32 -> 0 | P32: 0 | Q32: 0 | R32: 4 | S32: 367
A33: Atlântica Consultoria Internacional | B33: Agosto | C33: 8 | D33: 0 | E33: 0 | F33: =F32+D33 -> 0 | G33: =G32+E33 -> 0 | H33: 0 | I33: 0 | J33: =J32+H33 -> 0 | K33: =K32+I33 -> 0 | L33: 0 | M33: 0 | N33: =N32+L33 -> 0 | O33: =O32+M33 -> 0 | P33: 0 | Q33: 0 | R33: 4 | S33: 367
A34: Atlântica Consultoria Internacional | B34: Setembro | C34: 9 | D34: 0 | E34: 0 | F34: =F33+D34 -> 0 | G34: =G33+E34 -> 0 | H34: 0 | I34: 0 | J34: =J33+H34 -> 0 | K34: =K33+I34 -> 0 | L34: 0 | M34: 0 | N34: =N33+L34 -> 0 | O34: =O33+M34 -> 0 | P34: 3 | Q34: 3900 | R34: 7 | S34: 4267
A35: Atlântica Consultoria Internacional | B35: Outubro | C35: 10 | D35: 0 | E35: 0 | F35: =F34+D35 -> 0 | G35: =G34+E35 -> 0 | H35: 0 | I35: 0 | J35: =J34+H35 -> 0 | K35: =K34+I35 -> 0 | L35: 0 | M35: 0 | N35: =N34+L35 -> 0 | O35: =O34+M35 -> 0 | P35: 0 | Q35: 0 | R35: 7 | S35: 4267
A36: Atlântica Consultoria Internacional | B36: Novembro | C36: 11 | D36: 0 | E36: 0 | F36: =F35+D36 -> 0 | G36: =G35+E36 -> 0 | H36: 0 | I36: 0 | J36: =J35+H36 -> 0 | K36: =K35+I36 -> 0 | L36: 0 | M36: 0 | N36: =N35+L36 -> 0 | O36: =O35+M36 -> 0 | Q36: 0
A37: Atlântica Consultoria Internacional | B37: Dezembro | C37: 12 | D37: 0 | E37: 0 | F37: =F36+D37 -> 0 | G37: =G36+E37 -> 0 | H37: 0 | I37: 0 | J37: =J36+H37 -> 0 | K37: =K36+I37 -> 0 | L37: 0 | M37: 0 | N37: =N36+L37 -> 0 | O37: =O36+M37 -> 0 | Q37: 0
A38: Automatiza Júnior | B38: Janeiro | C38: 1 | D38: 0 | E38: 0 | F38: =D38 -> 0 | G38: =E38 -> 0 | H38: 0 | I38: 0 | J38: =H38 -> 0 | K38: =I38 -> 0 | L38: 0 | M38: 0 | N38: =L38 -> 0 | O38: =M38 -> 0 | P38: 0 | Q38: 0 | R38: 0 | S38: 0
A39: Automatiza Júnior | B39: Fevereiro | C39: 2 | D39: 0 | E39: 0 | F39: =F38+D39 -> 0 | G39: =G38+E39 -> 0 | H39: 0 | I39: 0 | J39: =J38+H39 -> 0 | K39: =K38+I39 -> 0 | L39: 0 | M39: 0 | N39: =N38+L39 -> 0 | O39: =O38+M39 -> 0 | P39: 1 | Q39: 900 | R39: 1 | S39: 900
A40: Automatiza Júnior | B40: Março | C40: 3 | D40: 0 | E40: 0 | F40: =F39+D40 -> 0 | G40: =G39+E40 -> 0 | H40: 0 | I40: 0 | J40: =J39+H40 -> 0 | K40: =K39+I40 -> 0 | L40: 0 | M40: 0 | N40: =N39+L40 -> 0 | O40: =O39+M40 -> 0 | P40: 2 | Q40: 3464.08 | R40: 3 | S40: 4364.08
...

Sheet Indicadores
A1: EMPRESA JÚNIOR | B1: Indice Mês | C1: Mês | D1: META de % de membros que executaram | E1: % DE MEMBROS QUE EXECUTARAM PROJETOS ACUMULADA | F1: Valor projetos | G1: Desempenho Execução de Projetos | H1: Média(Mensal) projetos | I1: Banda Superior (Mensal) projetos | J1: Banda Inferior (Mensal) projetos | K1: META de Faturamento | L1: FATURAMENTO | M1: INDICE faturamento | N1: Desempenho Faturamento | O1: Média Mensal faturamento | P1: Banda Superior (Mensal) faturamento | Q1: Banda Inferior (Mensal) faturamento | R1: META de % de participação em eventos | S1: % DE PARTICIPAÇÃO EM EVENTOS ACUMULADA | T1: Indicador Participação em Eventos | U1: Desempenho Participação em eventos | V1: Média eventos | W1: Banda Superior eventos | X1: Banda Inferior eventos | Y1: Banda Inferior Ajustada eventos | Z1: Desvio Padrão eventos
A2: AJTAL - ASSOCIAÇÃO JÚNIOR DE TECNÓLOGOS EM ALIMENTOS CONSULTORIA E PROJETOS | B2: =_xlfn.IFS(C2="Janeiro",1,C2="Fevereiro",2,C2="Março",3,C2="Abril",4,C2="Maio",5,C2="Junho",6,C2="Julho",7,C2="Agosto",8,C2="Setembro",9,C2="Outubro",10,C2="Novembro",11,C2="Dezembro",12,TRUE,0) -> 1 | C2: Janeiro | D2: 0 | E2: 0 | F2: =E2/D2 -> #DIV/0! | G2: =IF(F2>=#REF!,"Desempenho Ótimo",(IF(F2>#REF!,"Desempenho Bom",(IF(F2>#REF!,"Desempenho Médio",IF(F2<=#REF!,"Desempenho Deficitário",0)))))) -> #DIV/0! | H2: ='Cálculo Banda Part. Proj'!BM2 -> #DIV/0! | I2: ='Cálculo Banda Part. Proj'!BN2 -> #DIV/0! | J2: ='Cálculo Banda Part. Proj'!BO2 -> #DIV/0! | K2: 0 | L2: ='Monitoramento Acumulado Geral'!Q2 -> 0 | M2: =L2/K2 -> #DIV/0! | N2: =IF(M2>=#REF!,"Desempenho Ótimo",(IF(M2>#REF!,"Desempenho Bom",(IF(M2>#REF!,"Desempenho Médio",IF(M2<=#REF!,"Desempenho Deficitário",0)))))) -> #DIV/0! | O2: ='Cálculo Banda Faturamento'!BM2 -> #DIV/0! | P2: ='Cálculo Banda Faturamento'!BN2 -> #DIV/0! | Q2: ='Cálculo Banda Faturamento'!BO2 -> #DIV/0! | R2: 0 | S2: 0 | T2: =S2/R2 -> #DIV/0! | U2: =IF(T2>=#REF!,"Desempenho Ótimo",(IF(T2>#REF!,"Desempenho Bom",(IF(T2>#REF!,"Desempenho Médio",IF(T2<=#REF!,"Desempenho Deficitário",0)))))) -> #DIV/0! | V2: ='Cálculo Banda Part. Event.'!BM2 -> #DIV/0! | W2: ='Cálculo Banda Part. Event.'!BN2 -> #DIV/0! | X2: ='Cálculo Banda Part. Event.'!BO2 -> #DIV/0! | Y2: =IF(X2<0,X2+(Z2/2),X2) -> #DIV/0! | Z2: ='Cálculo Banda Part. Event.'!BP2 -> #DIV/0!
A3: AJTAL - ASSOCIAÇÃO JÚNIOR DE TECNÓLOGOS EM ALIMENTOS CONSULTORIA E PROJETOS | B3: =_xlfn.IFS(C3="Janeiro",1,C3="Fevereiro",2,C3="Março",3,C3="Abril",4,C3="Maio",5,C3="Junho",6,C3="Julho",7,C3="Agosto",8,C3="Setembro",9,C3="Outubro",10,C3="Novembro",11,C3="Dezembro",12,TRUE,0) -> 2 | C3: Fevereiro | D3: 0 | E3: 0 | F3: =E3/D3 -> #DIV/0! | G3: =IF(F3>=#REF!,"Desempenho Ótimo",(IF(F3>#REF!,"Desempenho Bom",(IF(F3>#REF!,"Desempenho Médio",IF(F3<=#REF!,"Desempenho Deficitário",0)))))) -> #DIV/0! | H3: ='Cálculo Banda Part. Proj'!BM3 -> #DIV/0! | I3: ='Cálculo Banda Part. Proj'!BN3 -> #DIV/0! | J3: ='Cálculo Banda Part. Proj'!BO3 -> #DIV/0! | K3: 0 | L3: ='Monitoramento Acumulado Geral'!Q3 -> 0 | M3: =(SUM(L2:L3))/K2 -> #DIV/0! | N3: =IF(M3>=#REF!,"Desempenho Ótimo",(IF(M3>#REF!,"Desempenho Bom",(IF(M3>#REF!,"Desempenho Médio",IF(M3<=#REF!,"Desempenho Deficitário",0)))))) -> #DIV/0! | O3: ='Cálculo Banda Faturamento'!BM3 -> #DIV/0! | P3: ='Cálculo Banda Faturamento'!BN3 -> #DIV/0! | Q3: ='Cálculo Banda Faturamento'!BO3 -> #DIV/0! | R3: 0 | S3: 0 | T3: =S3/R3 -> #DIV/0! | U3: =IF(T3>=#REF!,"Desempenho Ótimo",(IF(T3>#REF!,"Desempenho Bom",(IF(T3>#REF!,"Desempenho Médio",IF(T3<=#REF!,"Desempenho Deficitário",0)))))) -> #DIV/0! | V3: ='Cálculo Banda Part. Event.'!BM3 -> #DIV/0! | W3: ='Cálculo Banda Part. Event.'!BN3 -> #DIV/0! | X3: ='Cálculo Banda Part. Event.'!BO3 -> #DIV/0! | Y3: =IF(X3<0,X3+(Z3/2),X3) -> #DIV/0! | Z3: ='Cálculo Banda Part. Event.'!BP3 -> #DIV/0!
A4: AJTAL - ASSOCIAÇÃO JÚNIOR DE TECNÓLOGOS EM ALIMENTOS CONSULTORIA E PROJETOS | B4: =_xlfn.IFS(C4="Janeiro",1,C4="Fevereiro",2,C4="Março",3,C4="Abril",4,C4="Maio",5,C4="Junho",6,C4="Julho",7,C4="Agosto",8,C4="Setembro",9,C4="Outubro",10,C4="Novembro",11,C4="Dezembro",12,TRUE,0) -> 3 | C4: Março | D4: 0 | E4: 0 | F4: =E4/D4 -> #DIV/0! | G4: =IF(F4>=#REF!,"Desempenho Ótimo",(IF(F4>#REF!,"Desempenho Bom",(IF(F4>#REF!,"Desempenho Médio",IF(F4<=#REF!,"Desempenho Deficitário",0)))))) -> #DIV/0! | H4: ='Cálculo Banda Part. Proj'!BM4 -> #DIV/0! | I4: ='Cálculo Banda Part. Proj'!BN4 -> #DIV/0! | J4: ='Cálculo Banda Part. Proj'!BO4 -> #DIV/0! | K4: 0 | L4: ='Monitoramento Acumulado Geral'!Q4 -> 0 | M4: =(SUM(L2:L4))/K3 -> #DIV/0! | N4: =IF(M4>=#REF!,"Desempenho Ótimo",(IF(M4>#REF!,"Desempenho Bom",(IF(M4>#REF!,"Desempenho Médio",IF(M4<=#REF!,"Desempenho Deficitário",0)))))) -> #DIV/0! | O4: ='Cálculo Banda Faturamento'!BM4 -> #DIV/0! | P4: ='Cálculo Banda Faturamento'!BN4 -> #DIV/0! | Q4: ='Cálculo Banda Faturamento'!BO4 -> #DIV/0! | R4: 0 | S4: 0 | T4: =S4/R4 -> #DIV/0! | U4: =IF(T4>=#REF!,"Desempenho Ótimo",(IF(T4>#REF!,"Desempenho Bom",(IF(T4>#REF!,"Desempenho Médio",IF(T4<=#REF!,"Desempenho Deficitário",0)))))) -> #DIV/0! | V4: ='Cálculo Banda Part. Event.'!BM4 -> #DIV/0! | W4: ='Cálculo Banda Part. Event.'!BN4 -> #DIV/0! | X4: ='Cálculo Banda Part. Event.'!BO4 -> #DIV/0! | Y4: =IF(X4<0,X4+(Z4/2),X4) -> #DIV/0! | Z4: ='Cálculo Banda Part. Event.'!BP4 -> #DIV/0!
A5: AJTAL - ASSOCIAÇÃO JÚNIOR DE TECNÓLOGOS EM ALIMENTOS CONSULTORIA E PROJETOS | B5: =_xlfn.IFS(C5="Janeiro",1,C5="Fevereiro",2,C5="Março",3,C5="Abril",4,C5="Maio",5,C5="Junho",6,C5="Julho",7,C5="Agosto",8,C5="Setembro",9,C5="Outubro",10,C5="Novembro",11,C5="Dezembro",12,TRUE,0) -> 4 | C5: Abril | D5: 0 | E5: 0 | F5: =E5/D5 -> #DIV/0! | G5: =IF(F5>=#REF!,"Desempenho Ótimo",(IF(F5>#REF!,"Desempenho Bom",(IF(F5>#REF!,"Desempenho Médio",IF(F5<=#REF!,"Desempenho Deficitário",0)))))) -> #DIV/0! | H5: ='Cálculo Banda Part. Proj'!BM5 -> #DIV/0! | I5: ='Cálculo Banda Part. Proj'!BN5 -> #DIV/0! | J5: ='Cálculo Banda Part. Proj'!BO5 -> #DIV/0! | K5: 0 | L5: ='Monitoramento Acumulado Geral'!Q5 -> 0 | M5: =(SUM(L2:L5))/K4 -> #DIV/0! | N5: =IF(M5>=#REF!,"Desempenho Ótimo",(IF(M5>#REF!,"Desempenho Bom",(IF(M5>#REF!,"Desempenho Médio",IF(M5<=#REF!,"Desempenho Deficitário",0)))))) -> #DIV/0! | O5: ='Cálculo Banda Faturamento'!BM5 -> #DIV/0! | P5: ='Cálculo Banda Faturamento'!BN5 -> #DIV/0! | Q5: ='Cálculo Banda Faturamento'!BO5 -> #DIV/0! | R5: 0 | S5: 0 | T5: =S5/R5 -> #DIV/0! | U5: =IF(T5>=#REF!,"Desempenho Ótimo",(IF(T5>#REF!,"Desempenho Bom",(IF(T5>#REF!,"Desempenho Médio",IF(T5<=#REF!,"Desempenho Deficitário",0)))))) -> #DIV/0! | V5: ='Cálculo Banda Part. Event.'!BM5 -> #DIV/0! | W5: ='Cálculo Banda Part. Event.'!BN5 -> #DIV/0! | X5: ='Cálculo Banda Part. Event.'!BO5 -> #DIV/0! | Y5: =IF(X5<0,X5+(Z5/2),X5) -> #DIV/0! | Z5: ='Cálculo Banda Part. Event.'!BP5 -> #DIV/0!
A6: AJTAL - ASSOCIAÇÃO JÚNIOR DE TECNÓLOGOS EM ALIMENTOS CONSULTORIA E PROJETOS | B6: =_xlfn.IFS(C6="Janeiro",1,C6="Fevereiro",2,C6="Março",3,C6="Abril",4,C6="Maio",5,C6="Junho",6,C6="Julho",7,C6="Agosto",8,C6="Setembro",9,C6="Outubro",10,C6="Novembro",11,C6="Dezembro",12,TRUE,0) -> 5 | C6: Maio | D6: 0 | E6: 0 | F6: =E6/D6 -> #DIV/0! | G6: =IF(F6>=#REF!,"Desempenho Ótimo",(IF(F6>#REF!,"Desempenho Bom",(IF(F6>#REF!,"Desempenho Médio",IF(F6<=#REF!,"Desempenho Deficitário",0)))))) -> #DIV/0! | H6: ='Cálculo Banda Part. Proj'!BM6 -> #DIV/0! | I6: ='Cálculo Banda Part. Proj'!BN6 -> #DIV/0! | J6: ='Cálculo Banda Part. Proj'!BO6 -> #DIV/0! | K6: 0 | L6: ='Monitoramento Acumulado Geral'!Q6 -> 0 | M6: =(SUM(L2:L6))/K5 -> #DIV/0! | N6: =IF(M6>=#REF!,"Desempenho Ótimo",(IF(M6>#REF!,"Desempenho Bom",(IF(M6>#REF!,"Desempenho Médio",IF(M6<=#REF!,"Desempenho Deficitário",0)))))) -> #DIV/0! | O6: ='Cálculo Banda Faturamento'!BM6 -> #DIV/0! | P6: ='Cálculo Banda Faturamento'!BN6 -> #DIV/0! | Q6: ='Cálculo Banda Faturamento'!BO6 -> #DIV/0! | R6: 0 | S6: 0 | T6: =S6/R6 -> #DIV/0! | U6: =IF(T6>=#REF!,"Desempenho Ótimo",(IF(T6>#REF!,"Desempenho Bom",(IF(T6>#REF!,"Desempenho Médio",IF(T6<=#REF!,"Desempenho Deficitário",0)))))) -> #DIV/0! | V6: ='Cálculo Banda Part. Event.'!BM6 -> #DIV/0! | W6: ='Cálculo Banda Part. Event.'!BN6 -> #DIV/0! | X6: ='Cálculo Banda Part. Event.'!BO6 -> #DIV/0! | Y6: =IF(X6<0,X6+(Z6/2),X6) -> #DIV/0! | Z6: ='Cálculo Banda Part. Event.'!BP6 -> #DIV/0!
A7: AJTAL - ASSOCIAÇÃO JÚNIOR DE TECNÓLOGOS EM ALIMENTOS CONSULTORIA E PROJETOS | B7: =_xlfn.IFS(C7="Janeiro",1,C7="Fevereiro",2,C7="Março",3,C7="Abril",4,C7="Maio",5,C7="Junho",6,C7="Julho",7,C7="Agosto",8,C7="Setembro",9,C7="Outubro",10,C7="Novembro",11,C7="Dezembro",12,TRUE,0) -> 6 | C7: Junho | D7: 0 | E7: 0 | F7: =E7/D7 -> #DIV/0! | G7: =IF(F7>=#REF!,"Desempenho Ótimo",(IF(F7>#REF!,"Desempenho Bom",(IF(F7>#REF!,"Desempenho Médio",IF(F7<=#REF!,"Desempenho Deficitário",0)))))) -> #DIV/0! | H7: ='Cálculo Banda Part. Proj'!BM7 -> #DIV/0! | I7: ='Cálculo Banda Part. Proj'!BN7 -> #DIV/0! | J7: ='Cálculo Banda Part. Proj'!BO7 -> #DIV/0! | K7: 0 | L7: ='Monitoramento Acumulado Geral'!Q7 -> 0 | M7: =(SUM(L2:L7))/K6 -> #DIV/0! | N7: =IF(M7>=#REF!,"Desempenho Ótimo",(IF(M7>#REF!,"Desempenho Bom",(IF(M7>#REF!,"Desempenho Médio",IF(M7<=#REF!,"Desempenho Deficitário",0)))))) -> #DIV/0! | O7: ='Cálculo Banda Faturamento'!BM7 -> #DIV/0! | P7: ='Cálculo Banda Faturamento'!BN7 -> #DIV/0! | Q7: ='Cálculo Banda Faturamento'!BO7 -> #DIV/0! | R7: 0 | S7: 0 | T7: =S7/R7 -> #DIV/0! | U7: =IF(T7>=#REF!,"Desempenho Ótimo",(IF(T7>#REF!,"Desempenho Bom",(IF(T7>#REF!,"Desempenho Médio",IF(T7<=#REF!,"Desempenho Deficitário",0)))))) -> #DIV/0! | V7: ='Cálculo Banda Part. Event.'!BM7 -> #DIV/0! | W7: ='Cálculo Banda Part. Event.'!BN7 -> #DIV/0! | X7: ='Cálculo Banda Part. Event.'!BO7 -> #DIV/0! | Y7: =IF(X7<0,X7+(Z7/2),X7) -> #DIV/0! | Z7: ='Cálculo Banda Part. Event.'!BP7 -> #DIV/0!
A8: AJTAL - ASSOCIAÇÃO JÚNIOR DE TECNÓLOGOS EM ALIMENTOS CONSULTORIA E PROJETOS | B8: =_xlfn.IFS(C8="Janeiro",1,C8="Fevereiro",2,C8="Março",3,C8="Abril",4,C8="Maio",5,C8="Junho",6,C8="Julho",7,C8="Agosto",8,C8="Setembro",9,C8="Outubro",10,C8="Novembro",11,C8="Dezembro",12,TRUE,0) -> 7 | C8: Julho | D8: 0 | E8: 0 | F8: =E8/D8 -> #DIV/0! | G8: =IF(F8>=#REF!,"Desempenho Ótimo",(IF(F8>#REF!,"Desempenho Bom",(IF(F8>#REF!,"Desempenho Médio",IF(F8<=#REF!,"Desempenho Deficitário",0)))))) -> #DIV/0! | H8: ='Cálculo Banda Part. Proj'!BM8 -> #DIV/0! | I8: ='Cálculo Banda Part. Proj'!BN8 -> #DIV/0! | J8: ='Cálculo Banda Part. Proj'!BO8 -> #DIV/0! | K8: 0 | L8: ='Monitoramento Acumulado Geral'!Q8 -> 0 | M8: =(SUM(L2:L8))/K7 -> #DIV/0! | N8: =IF(M8>=#REF!,"Desempenho Ótimo",(IF(M8>#REF!,"Desempenho Bom",(IF(M8>#REF!,"Desempenho Médio",IF(M8<=#REF!,"Desempenho Deficitário",0)))))) -> #DIV/0! | O8: ='Cálculo Banda Faturamento'!BM8 -> #DIV/0! | P8: ='Cálculo Banda Faturamento'!BN8 -> #DIV/0! | Q8: ='Cálculo Banda Faturamento'!BO8 -> #DIV/0! | R8: 0 | S8: 0 | T8: =S8/R8 -> #DIV/0! | U8: =IF(T8>=#REF!,"Desempenho Ótimo",(IF(T8>#REF!,"Desempenho Bom",(IF(T8>#REF!,"Desempenho Médio",IF(T8<=#REF!,"Desempenho Deficitário",0)))))) -> #DIV/0! | V8: ='Cálculo Banda Part. Event.'!BM8 -> #DIV/0! | W8: ='Cálculo Banda Part. Event.'!BN8 -> #DIV/0! | X8: ='Cálculo Banda Part. Event.'!BO8 -> #DIV/0! | Y8: =IF(X8<0,X8+(Z8/2),X8) -> #DIV/0! | Z8: ='Cálculo Banda Part. Event.'!BP8 -> #DIV/0!
A9: AJTAL - ASSOCIAÇÃO JÚNIOR DE TECNÓLOGOS EM ALIMENTOS CONSULTORIA E PROJETOS | B9: =_xlfn.IFS(C9="Janeiro",1,C9="Fevereiro",2,C9="Março",3,C9="Abril",4,C9="Maio",5,C9="Junho",6,C9="Julho",7,C9="Agosto",8,C9="Setembro",9,C9="Outubro",10,C9="Novembro",11,C9="Dezembro",12,TRUE,0) -> 8 | C9: Agosto | D9: 0 | E9: 44 | F9: =E9/D9 -> #DIV/0! | G9: =IF(F9>=#REF!,"Desempenho Ótimo",(IF(F9>#REF!,"Desempenho Bom",(IF(F9>#REF!,"Desempenho Médio",IF(F9<=#REF!,"Desempenho Deficitário",0)))))) -> #DIV/0! | H9: ='Cálculo Banda Part. Proj'!BM9 -> #DIV/0! | I9: ='Cálculo Banda Part. Proj'!BN9 -> #DIV/0! | J9: ='Cálculo Banda Part. Proj'!BO9 -> #DIV/0! | K9: 0 | L9: ='Monitoramento Acumulado Geral'!Q9 -> 240 | M9: =(SUM(L2:L9))/K8 -> #DIV/0! | N9: =IF(M9>=#REF!,"Desempenho Ótimo",(IF(M9>#REF!,"Desempenho Bom",(IF(M9>#REF!,"Desempenho Médio",IF(M9<=#REF!,"Desempenho Deficitário",0)))))) -> #DIV/0! | O9: ='Cálculo Banda Faturamento'!BM9 -> #DIV/0! | P9: ='Cálculo Banda Faturamento'!BN9 -> #DIV/0! | Q9: ='Cálculo Banda Faturamento'!BO9 -> #DIV/0! | R9: 0 | S9: 0 | T9: =S9/R9 -> #DIV/0! | U9: =IF(T9>=#REF!,"Desempenho Ótimo",(IF(T9>#REF!,"Desempenho Bom",(IF(T9>#REF!,"Desempenho Médio",IF(T9<=#REF!,"Desempenho Deficitário",0)))))) -> #DIV/0! | V9: ='Cálculo Banda Part. Event.'!BM9 -> #DIV/0! | W9: ='Cálculo Banda Part. Event.'!BN9 -> #DIV/0! | X9: ='Cálculo Banda Part. Event.'!BO9 -> #DIV/0! | Y9: =IF(X9<0,X9+(Z9/2),X9) -> #DIV/0! | Z9: ='Cálculo Banda Part. Event.'!BP9 -> #DIV/0!
A10: AJTAL - ASSOCIAÇÃO JÚNIOR DE TECNÓLOGOS EM ALIMENTOS CONSULTORIA E PROJETOS | B10: =_xlfn.IFS(C10="Janeiro",1,C10="Fevereiro",2,C10="Março",3,C10="Abril",4,C10="Maio",5,C10="Junho",6,C10="Julho",7,C10="Agosto",8,C10="Setembro",9,C10="Outubro",10,C10="Novembro",11,C10="Dezembro",12,TRUE,0) -> 9 | C10: Setembro | D10: 0 | E10: 44 | F10: =E10/D10 -> #DIV/0! | G10: =IF(F10>=#REF!,"Desempenho Ótimo",(IF(F10>#REF!,"Desempenho Bom",(IF(F10>#REF!,"Desempenho Médio",IF(F10<=#REF!,"Desempenho Deficitário",0)))))) -> #DIV/0! | H10: ='Cálculo Banda Part. Proj'!BM10 -> #DIV/0! | I10: ='Cálculo Banda Part. Proj'!BN10 -> #DIV/0! | J10: ='Cálculo Banda Part. Proj'!BO10 -> #DIV/0! | K10: 0 | L10: ='Monitoramento Acumulado Geral'!Q10 -> 0 | M10: =(SUM(L2:L10))/K9 -> #DIV/0! | N10: =IF(M10>=#REF!,"Desempenho Ótimo",(IF(M10>#REF!,"Desempenho Bom",(IF(M10>#REF!,"Desempenho Médio",IF(M10<=#REF!,"Desempenho Deficitário",0)))))) -> #DIV/0! | O10: ='Cálculo Banda Faturamento'!BM10 -> #DIV/0! | P10: ='Cálculo Banda Faturamento'!BN10 -> #DIV/0! | Q10: ='Cálculo Banda Faturamento'!BO10 -> #DIV/0! | R10: 0 | S10: 0 | T10: =S10/R10 -> #DIV/0! | U10: =IF(T10>=#REF!,"Desempenho Ótimo",(IF(T10>#REF!,"Desempenho Bom",(IF(T10>#REF!,"Desempenho Médio",IF(T10<=#REF!,"Desempenho Deficitário",0)))))) -> #DIV/0! | V10: ='Cálculo Banda Part. Event.'!BM10 -> #DIV/0! | W10: ='Cálculo Banda Part. Event.'!BN10 -> #DIV/0! | X10: ='Cálculo Banda Part. Event.'!BO10 -> #DIV/0! | Y10: =IF(X10<0,X10+(Z10/2),X10) -> #DIV/0! | Z10: ='Cálculo Banda Part. Event.'!BP10 -> #DIV/0!
A11: AJTAL - ASSOCIAÇÃO JÚNIOR DE TECNÓLOGOS EM ALIMENTOS CONSULTORIA E PROJETOS | B11: =_xlfn.IFS(C11="Janeiro",1,C11="Fevereiro",2,C11="Março",3,C11="Abril",4,C11="Maio",5,C11="Junho",6,C11="Julho",7,C11="Agosto",8,C11="Setembro",9,C11="Outubro",10,C11="Novembro",11,C11="Dezembro",12,TRUE,0) -> 10 | C11: Outubro | D11: 0 | E11: 44 | F11: =E11/D11 -> #DIV/0! | G11: =IF(F11>=#REF!,"Desempenho Ótimo",(IF(F11>#REF!,"Desempenho Bom",(IF(F11>#REF!,"Desempenho Médio",IF(F11<=#REF!,"Desempenho Deficitário",0)))))) -> #DIV/0! | H11: ='Cálculo Banda Part. Proj'!BM11 -> #DIV/0! | I11: ='Cálculo Banda Part. Proj'!BN11 -> #DIV/0! | J11: ='Cálculo Banda Part. Proj'!BO11 -> #DIV/0! | K11: 0 | L11: ='Monitoramento Acumulado Geral'!Q11 -> 0 | M11: =(SUM(L2:L11))/K10 -> #DIV/0! | N11: =IF(M11>=#REF!,"Desempenho Ótimo",(IF(M11>#REF!,"Desempenho Bom",(IF(M11>#REF!,"Desempenho Médio",IF(M11<=#REF!,"Desempenho Deficitário",0)))))) -> #DIV/0! | O11: ='Cálculo Banda Faturamento'!BM11 -> #DIV/0! | P11: ='Cálculo Banda Faturamento'!BN11 -> #DIV/0! | Q11: ='Cálculo Banda Faturamento'!BO11 -> #DIV/0! | R11: 0 | S11: 0 | T11: =S11/R11 -> #DIV/0! | U11: =IF(T11>=#REF!,"Desempenho Ótimo",(IF(T11>#REF!,"Desempenho Bom",(IF(T11>#REF!,"Desempenho Médio",IF(T11<=#REF!,"Desempenho Deficitário",0)))))) -> #DIV/0! | V11: ='Cálculo Banda Part. Event.'!BM11 -> #DIV/0! | W11: ='Cálculo Banda Part. Event.'!BN11 -> #DIV/0! | X11: ='Cálculo Banda Part. Event.'!BO11 -> #DIV/0! | Y11: =IF(X11<0,X11+(Z11/2),X11) -> #DIV/0! | Z11: ='Cálculo Banda Part. Event.'!BP11 -> #DIV/0!
A12: AJTAL - ASSOCIAÇÃO JÚNIOR DE TECNÓLOGOS EM ALIMENTOS CONSULTORIA E PROJETOS | B12: =_xlfn.IFS(C12="Janeiro",1,C12="Fevereiro",2,C12="Março",3,C12="Abril",4,C12="Maio",5,C12="Junho",6,C12="Julho",7,C12="Agosto",8,C12="Setembro",9,C12="Outubro",10,C12="Novembro",11,C12="Dezembro",12,TRUE,0) -> 11 | C12: Novembro | D12: 0 | F12: =E12/D12 -> #DIV/0! | G12: =IF(F12>=#REF!,"Desempenho Ótimo",(IF(F12>#REF!,"Desempenho Bom",(IF(F12>#REF!,"Desempenho Médio",IF(F12<=#REF!,"Desempenho Deficitário",0)))))) -> #DIV/0! | H12: ='Cálculo Banda Part. Proj'!BM12 -> #DIV/0! | I12: ='Cálculo Banda Part. Proj'!BN12 -> #DIV/0! | J12: ='Cálculo Banda Part. Proj'!BO12 -> #DIV/0! | K12: 0 | L12: ='Monitoramento Acumulado Geral'!Q12 -> 0 | M12: =(SUM(L2:L12))/K11 -> #DIV/0! | N12: =IF(M12>=#REF!,"Desempenho Ótimo",(IF(M12>#REF!,"Desempenho Bom",(IF(M12>#REF!,"Desempenho Médio",IF(M12<=#REF!,"Desempenho Deficitário",0)))))) -> #DIV/0! | O12: ='Cálculo Banda Faturamento'!BM12 -> #DIV/0! | P12: ='Cálculo Banda Faturamento'!BN12 -> #DIV/0! | Q12: ='Cálculo Banda Faturamento'!BO12 -> #DIV/0! | R12: 0 | S12: 0 | T12: =S12/R12 -> #DIV/0! | U12: =IF(T12>=#REF!,"Desempenho Ótimo",(IF(T12>#REF!,"Desempenho Bom",(IF(T12>#REF!,"Desempenho Médio",IF(T12<=#REF!,"Desempenho Deficitário",0)))))) -> #DIV/0! | V12: ='Cálculo Banda Part. Event.'!BM12 -> #DIV/0! | W12: ='Cálculo Banda Part. Event.'!BN12 -> #DIV/0! | X12: ='Cálculo Banda Part. Event.'!BO12 -> #DIV/0! | Y12: =IF(X12<0,X12+(Z12/2),X12) -> #DIV/0! | Z12: ='Cálculo Banda Part. Event.'!BP12 -> #DIV/0!
A13: AJTAL - ASSOCIAÇÃO JÚNIOR DE TECNÓLOGOS EM ALIMENTOS CONSULTORIA E PROJETOS | B13: =_xlfn.IFS(C13="Janeiro",1,C13="Fevereiro",2,C13="Março",3,C13="Abril",4,C13="Maio",5,C13="Junho",6,C13="Julho",7,C13="Agosto",8,C13="Setembro",9,C13="Outubro",10,C13="Novembro",11,C13="Dezembro",12,TRUE,0) -> 12 | C13: Dezembro | D13: 0 | F13: =E13/D13 -> #DIV/0! | G13: =IF(F13>=#REF!,"Desempenho Ótimo",(IF(F13>#REF!,"Desempenho Bom",(IF(F13>#REF!,"Desempenho Médio",IF(F13<=#REF!,"Desempenho Deficitário",0)))))) -> #DIV/0! | H13: ='Cálculo Banda Part. Proj'!BM13 -> #DIV/0! | I13: ='Cálculo Banda Part. Proj'!BN13 -> #DIV/0! | J13: ='Cálculo Banda Part. Proj'!BO13 -> #DIV/0! | K13: 0 | L13: ='Monitoramento Acumulado Geral'!Q13 -> 0 | M13: =(SUM(L2:L13))/K12 -> #DIV/0! | N13: =IF(M13>=P1,"Desempenho Ótimo",(IF(M13>O1,"Desempenho Bom",(IF(M13>Q1,"Desempenho Médio",IF(M13<=Q1,"Desempenho Deficitário",0)))))) -> #DIV/0! | O13: ='Cálculo Banda Faturamento'!BM13 -> #DIV/0! | P13: ='Cálculo Banda Faturamento'!BN13 -> #DIV/0! | Q13: ='Cálculo Banda Faturamento'!BO13 -> #DIV/0! | R13: 0 | S13: 0 | T13: =S13/R13 -> #DIV/0! | U13: =IF(T13>=#REF!,"Desempenho Ótimo",(IF(T13>#REF!,"Desempenho Bom",(IF(T13>#REF!,"Desempenho Médio",IF(T13<=#REF!,"Desempenho Deficitário",0)))))) -> #DIV/0! | V13: ='Cálculo Banda Part. Event.'!BM13 -> #DIV/0! | W13: ='Cálculo Banda Part. Event.'!BN13 -> #DIV/0! | X13: ='Cálculo Banda Part. Event.'!BO13 -> #DIV/0! | Y13: =IF(X13<0,X13+(Z13/2),X13) -> #DIV/0! | Z13: ='Cálculo Banda Part. Event.'!BP13 -> #DIV/0!
A14: Atena Consultoria Jr. | B14: =_xlfn.IFS(C14="Janeiro",1,C14="Fevereiro",2,C14="Março",3,C14="Abril",4,C14="Maio",5,C14="Junho",6,C14="Julho",7,C14="Agosto",8,C14="Setembro",9,C14="Outubro",10,C14="Novembro",11,C14="Dezembro",12,TRUE,0) -> 1 | C14: Janeiro | D14: 75 | E14: 50 | F14: =E14/D14 -> 0.66666667 | G14: =IF(F14>=I2,"Desempenho Ótimo",(IF(F14>H2,"Desempenho Bom",(IF(F14>J2,"Desempenho Médio",IF(F14<=J2,"Desempenho Deficitário",0)))))) -> #DIV/0! | H14: =H2 -> #DIV/0! | I14: =I2 -> #DIV/0! | J14: =J2 -> #DIV/0! | K14: 16700 | L14: ='Monitoramento Acumulado Geral'!Q14 -> 1892 | M14: =L14/K14 -> 0.11329341 | N14: =IF(M14>=P2,"Desempenho Ótimo",(IF(M14>O2,"Desempenho Bom",(IF(M14>Q2,"Desempenho Médio",IF(M14<=Q2,"Desempenho Deficitário",0)))))) -> #DIV/0! | O14: =O2 -> #DIV/0! | P14: =P2 -> #DIV/0! | Q14: =Q2 -> #DIV/0! | R14: 80 | S14: 0 | T14: =S14/R14 -> 0 | U14: =IF(T14>=W2,"Desempenho Ótimo",(IF(T14>V2,"Desempenho Bom",(IF(T14>X2,"Desempenho Médio",IF(T14<=X2,"Desempenho Deficitário",0)))))) -> #DIV/0! | V14: =V2 -> #DIV/0! | W14: =W2 -> #DIV/0! | X14: =X2 -> #DIV/0! | Y14: =Y2 -> #DIV/0! | Z14: =Z2 -> #DIV/0!
A15: Atena Consultoria Jr. | B15: =_xlfn.IFS(C15="Janeiro",1,C15="Fevereiro",2,C15="Março",3,C15="Abril",4,C15="Maio",5,C15="Junho",6,C15="Julho",7,C15="Agosto",8,C15="Setembro",9,C15="Outubro",10,C15="Novembro",11,C15="Dezembro",12,TRUE,0) -> 2 | C15: Fevereiro | D15: 75 | E15: 100 | F15: =E15/D15 -> 1.3333333 | G15: =IF(F15>=I3,"Desempenho Ótimo",(IF(F15>H3,"Desempenho Bom",(IF(F15>J3,"Desempenho Médio",IF(F15<=J3,"Desempenho Deficitário",0)))))) -> #DIV/0! | H15: =H3 -> #DIV/0! | I15: =I3 -> #DIV/0! | J15: =J3 -> #DIV/0! | K15: 16700 | L15: ='Monitoramento Acumulado Geral'!Q15 -> 5605 | M15: =(SUM(L14:L15))/K14 -> 0.44892216 | N15: =IF(M15>=P3,"Desempenho Ótimo",(IF(M15>O3,"Desempenho Bom",(IF(M15>Q3,"Desempenho Médio",IF(M15<=Q3,"Desempenho Deficitário",0)))))) -> #DIV/0! | O15: =O3 -> #DIV/0! | P15: =P3 -> #DIV/0! | Q15: =Q3 -> #DIV/0! | R15: 80 | S15: 0 | T15: =S15/R15 -> 0 | U15: =IF(T15>=W3,"Desempenho Ótimo",(IF(T15>V3,"Desempenho Bom",(IF(T15>X3,"Desempenho Médio",IF(T15<=X3,"Desempenho Deficitário",0)))))) -> #DIV/0! | V15: =V3 -> #DIV/0! | W15: =W3 -> #DIV/0! | X15: =X3 -> #DIV/0! | Y15: =Y3 -> #DIV/0! | Z15: =Z3 -> #DIV/0!
A16: Atena Consultoria Jr. | B16: =_xlfn.IFS(C16="Janeiro",1,C16="Fevereiro",2,C16="Março",3,C16="Abril",4,C16="Maio",5,C16="Junho",6,C16="Julho",7,C16="Agosto",8,C16="Setembro",9,C16="Outubro",10,C16="Novembro",11,C16="Dezembro",12,TRUE,0) -> 3 | C16: Março | D16: 75 | E16: 100 | F16: =E16/D16 -> 1.3333333 | G16: =IF(F16>=I4,"Desempenho Ótimo",(IF(F16>H4,"Desempenho Bom",(IF(F16>J4,"Desempenho Médio",IF(F16<=J4,"Desempenho Deficitário",0)))))) -> #DIV/0! | H16: =H4 -> #DIV/0! | I16: =I4 -> #DIV/0! | J16: =J4 -> #DIV/0! | K16: 16700 | L16: ='Monitoramento Acumulado Geral'!Q16 -> 0 | M16: =(SUM(L14:L16))/K15 -> 0.44892216 | N16: =IF(M16>=P4,"Desempenho Ótimo",(IF(M16>O4,"Desempenho Bom",(IF(M16>Q4,"Desempenho Médio",IF(M16<=Q4,"Desempenho Deficitário",0)))))) -> #DIV/0! | O16: =O4 -> #DIV/0! | P16: =P4 -> #DIV/0! | Q16: =Q4 -> #DIV/0! | R16: 80 | S16: 0 | T16: =S16/R16 -> 0 | U16: =IF(T16>=W4,"Desempenho Ótimo",(IF(T16>V4,"Desempenho Bom",(IF(T16>X4,"Desempenho Médio",IF(T16<=X4,"Desempenho Deficitário",0)))))) -> #DIV/0! | V16: =V4 -> #DIV/0! | W16: =W4 -> #DIV/0! | X16: =X4 -> #DIV/0! | Y16: =Y4 -> #DIV/0! | Z16: =Z4 -> #DIV/0!
A17: Atena Consultoria Jr. | B17: =_xlfn.IFS(C17="Janeiro",1,C17="Fevereiro",2,C17="Março",3,C17="Abril",4,C17="Maio",5,C17="Junho",6,C17="Julho",7,C17="Agosto",8,C17="Setembro",9,C17="Outubro",10,C17="Novembro",11,C17="Dezembro",12,TRUE,0) -> 4 | C17: Abril | D17: 75 | E17: 100 | F17: =E17/D17 -> 1.3333333 | G17: =IF(F17>=I5,"Desempenho Ótimo",(IF(F17>H5,"Desempenho Bom",(IF(F17>J5,"Desempenho Médio",IF(F17<=J5,"Desempenho Deficitário",0)))))) -> #DIV/0! | H17: =H5 -> #DIV/0! | I17: =I5 -> #DIV/0! | J17: =J5 -> #DIV/0! | K17: 16700 | L17: ='Monitoramento Acumulado Geral'!Q17 -> 0 | M17: =(SUM(L14:L17))/K16 -> 0.44892216 | N17: =IF(M17>=P5,"Desempenho Ótimo",(IF(M17>O5,"Desempenho Bom",(IF(M17>Q5,"Desempenho Médio",IF(M17<=Q5,"Desempenho Deficitário",0)))))) -> #DIV/0! | O17: =O5 -> #DIV/0! | P17: =P5 -> #DIV/0! | Q17: =Q5 -> #DIV/0! | R17: 80 | S17: 0 | T17: =S17/R17 -> 0 | U17: =IF(T17>=W5,"Desempenho Ótimo",(IF(T17>V5,"Desempenho Bom",(IF(T17>X5,"Desempenho Médio",IF(T17<=X5,"Desempenho Deficitário",0)))))) -> #DIV/0! | V17: =V5 -> #DIV/0! | W17: =W5 -> #DIV/0! | X17: =X5 -> #DIV/0! | Y17: =Y5 -> #DIV/0! | Z17: =Z5 -> #DIV/0!
A18: Atena Consultoria Jr. | B18: =_xlfn.IFS(C18="Janeiro",1,C18="Fevereiro",2,C18="Março",3,C18="Abril",4,C18="Maio",5,C18="Junho",6,C18="Julho",7,C18="Agosto",8,C18="Setembro",9,C18="Outubro",10,C18="Novembro",11,C18="Dezembro",12,TRUE,0) -> 5 | C18: Maio | D18: 75 | E18: 100 | F18: =E18/D18 -> 1.3333333 | G18: =IF(F18>=I6,"Desempenho Ótimo",(IF(F18>H6,"Desempenho Bom",(IF(F18>J6,"Desempenho Médio",IF(F18<=J6,"Desempenho Deficitário",0)))))) -> #DIV/0! | H18: =H6 -> #DIV/0! | I18: =I6 -> #DIV/0! | J18: =J6 -> #DIV/0! | K18: 16700 | L18: ='Monitoramento Acumulado Geral'!Q18 -> 0 | M18: =(SUM(L14:L18))/K17 -> 0.44892216 | N18: =IF(M18>=P6,"Desempenho Ótimo",(IF(M18>O6,"Desempenho Bom",(IF(M18>Q6,"Desempenho Médio",IF(M18<=Q6,"Desempenho Deficitário",0)))))) -> #DIV/0! | O18: =O6 -> #DIV/0! | P18: =P6 -> #DIV/0! | Q18: =Q6 -> #DIV/0! | R18: 80 | S18: 100 | T18: =S18/R18 -> 1.25 | U18: =IF(T18>=W6,"Desempenho Ótimo",(IF(T18>V6,"Desempenho Bom",(IF(T18>X6,"Desempenho Médio",IF(T18<=X6,"Desempenho Deficitário",0)))))) -> #DIV/0! | V18: =V6 -> #DIV/0! | W18: =W6 -> #DIV/0! | X18: =X6 -> #DIV/0! | Y18: =Y6 -> #DIV/0! | Z18: =Z6 -> #DIV/0!
A19: Atena Consultoria Jr. | B19: =_xlfn.IFS(C19="Janeiro",1,C19="Fevereiro",2,C19="Março",3,C19="Abril",4,C19="Maio",5,C19="Junho",6,C19="Julho",7,C19="Agosto",8,C19="Setembro",9,C19="Outubro",10,C19="Novembro",11,C19="Dezembro",12,TRUE,0) -> 6 | C19: Junho | D19: 75 | E19: 100 | F19: =E19/D19 -> 1.3333333 | G19: =IF(F19>=I7,"Desempenho Ótimo",(IF(F19>H7,"Desempenho Bom",(IF(F19>J7,"Desempenho Médio",IF(F19<=J7,"Desempenho Deficitário",0)))))) -> #DIV/0! | H19: =H7 -> #DIV/0! | I19: =I7 -> #DIV/0! | J19: =J7 -> #DIV/0! | K19: 16700 | L19: ='Monitoramento Acumulado Geral'!Q19 -> 2220 | M19: =(SUM(L14:L19))/K18 -> 0.58185629 | N19: =IF(M19>=P7,"Desempenho Ótimo",(IF(M19>O7,"Desempenho Bom",(IF(M19>Q7,"Desempenho Médio",IF(M19<=Q7,"Desempenho Deficitário",0)))))) -> #DIV/0! | O19: =O7 -> #DIV/0! | P19: =P7 -> #DIV/0! | Q19: =Q7 -> #DIV/0! | R19: 80 | S19: 100 | T19: =S19/R19 -> 1.25 | U19: =IF(T19>=W7,"Desempenho Ótimo",(IF(T19>V7,"Desempenho Bom",(IF(T19>X7,"Desempenho Médio",IF(T19<=X7,"Desempenho Deficitário",0)))))) -> #DIV/0! | V19: =V7 -> #DIV/0! | W19: =W7 -> #DIV/0! | X19: =X7 -> #DIV/0! | Y19: =Y7 -> #DIV/0! | Z19: =Z7 -> #DIV/0!
A20: Atena Consultoria Jr. | B20: =_xlfn.IFS(C20="Janeiro",1,C20="Fevereiro",2,C20="Março",3,C20="Abril",4,C20="Maio",5,C20="Junho",6,C20="Julho",7,C20="Agosto",8,C20="Setembro",9,C20="Outubro",10,C20="Novembro",11,C20="Dezembro",12,TRUE,0) -> 7 | C20: Julho | D20: 75 | E20: 100 | F20: =E20/D20 -> 1.3333333 | G20: =IF(F20>=I8,"Desempenho Ótimo",(IF(F20>H8,"Desempenho Bom",(IF(F20>J8,"Desempenho Médio",IF(F20<=J8,"Desempenho Deficitário",0)))))) -> #DIV/0! | H20: =H8 -> #DIV/0! | I20: =I8 -> #DIV/0! | J20: =J8 -> #DIV/0! | K20: 16700 | L20: ='Monitoramento Acumulado Geral'!Q20 -> 1800 | M20: =(SUM(L14:L20))/K19 -> 0.68964072 | N20: =IF(M20>=P8,"Desempenho Ótimo",(IF(M20>O8,"Desempenho Bom",(IF(M20>Q8,"Desempenho Médio",IF(M20<=Q8,"Desempenho Deficitário",0)))))) -> #DIV/0! | O20: =O8 -> #DIV/0! | P20: =P8 -> #DIV/0! | Q20: =Q8 -> #DIV/0! | R20: 80 | S20: 100 | T20: =S20/R20 -> 1.25 | U20: =IF(T20>=W8,"Desempenho Ótimo",(IF(T20>V8,"Desempenho Bom",(IF(T20>X8,"Desempenho Médio",IF(T20<=X8,"Desempenho Deficitário",0)))))) -> #DIV/0! | V20: =V8 -> #DIV/0! | W20: =W8 -> #DIV/0! | X20: =X8 -> #DIV/0! | Y20: =Y8 -> #DIV/0! | Z20: =Z8 -> #DIV/0!
A21: Atena Consultoria Jr. | B21: =_xlfn.IFS(C21="Janeiro",1,C21="Fevereiro",2,C21="Março",3,C21="Abril",4,C21="Maio",5,C21="Junho",6,C21="Julho",7,C21="Agosto",8,C21="Setembro",9,C21="Outubro",10,C21="Novembro",11,C21="Dezembro",12,TRUE,0) -> 8 | C21: Agosto | D21: 75 | E21: 100 | F21: =E21/D21 -> 1.3333333 | G21: =IF(F21>=I9,"Desempenho Ótimo",(IF(F21>H9,"Desempenho Bom",(IF(F21>J9,"Desempenho Médio",IF(F21<=J9,"Desempenho Deficitário",0)))))) -> #DIV/0! | H21: =H9 -> #DIV/0! | I21: =I9 -> #DIV/0! | J21: =J9 -> #DIV/0! | K21: 16700 | L21: ='Monitoramento Acumulado Geral'!Q21 -> 0 | M21: =(SUM(L14:L21))/K20 -> 0.68964072 | N21: =IF(M21>=P9,"Desempenho Ótimo",(IF(M21>O9,"Desempenho Bom",(IF(M21>Q9,"Desempenho Médio",IF(M21<=Q9,"Desempenho Deficitário",0)))))) -> #DIV/0! | O21: =O9 -> #DIV/0! | P21: =P9 -> #DIV/0! | Q21: =Q9 -> #DIV/0! | R21: 80 | S21: 100 | T21: =S21/R21 -> 1.25 | U21: =IF(T21>=W9,"Desempenho Ótimo",(IF(T21>V9,"Desempenho Bom",(IF(T21>X9,"Desempenho Médio",IF(T21<=X9,"Desempenho Deficitário",0)))))) -> #DIV/0! | V21: =V9 -> #DIV/0! | W21: =W9 -> #DIV/0! | X21: =X9 -> #DIV/0! | Y21: =Y9 -> #DIV/0! | Z21: =Z9 -> #DIV/0!
A22: Atena Consultoria Jr. | B22: =_xlfn.IFS(C22="Janeiro",1,C22="Fevereiro",2,C22="Março",3,C22="Abril",4,C22="Maio",5,C22="Junho",6,C22="Julho",7,C22="Agosto",8,C22="Setembro",9,C22="Outubro",10,C22="Novembro",11,C22="Dezembro",12,TRUE,0) -> 9 | C22: Setembro | D22: 75 | E22: 100 | F22: =E22/D22 -> 1.3333333 | G22: =IF(F22>=I10,"Desempenho Ótimo",(IF(F22>H10,"Desempenho Bom",(IF(F22>J10,"Desempenho Médio",IF(F22<=J10,"Desempenho Deficitário",0)))))) -> #DIV/0! | H22: =H10 -> #DIV/0! | I22: =I10 -> #DIV/0! | J22: =J10 -> #DIV/0! | K22: 16700 | L22: ='Monitoramento Acumulado Geral'!Q22 -> 0 | M22: =(SUM(L14:L22))/K21 -> 0.68964072 | N22: =IF(M22>=P10,"Desempenho Ótimo",(IF(M22>O10,"Desempenho Bom",(IF(M22>Q10,"Desempenho Médio",IF(M22<=Q10,"Desempenho Deficitário",0)))))) -> #DIV/0! | O22: =O10 -> #DIV/0! | P22: =P10 -> #DIV/0! | Q22: =Q10 -> #DIV/0! | R22: 80 | S22: 100 | T22: =S22/R22 -> 1.25 | U22: =IF(T22>=W10,"Desempenho Ótimo",(IF(T22>V10,"Desempenho Bom",(IF(T22>X10,"Desempenho Médio",IF(T22<=X10,"Desempenho Deficitário",0)))))) -> #DIV/0! | V22: =V10 -> #DIV/0! | W22: =W10 -> #DIV/0! | X22: =X10 -> #DIV/0! | Y22: =Y10 -> #DIV/0! | Z22: =Z10 -> #DIV/0!
A23: Atena Consultoria Jr. | B23: =_xlfn.IFS(C23="Janeiro",1,C23="Fevereiro",2,C23="Março",3,C23="Abril",4,C23="Maio",5,C23="Junho",6,C23="Julho",7,C23="Agosto",8,C23="Setembro",9,C23="Outubro",10,C23="Novembro",11,C23="Dezembro",12,TRUE,0) -> 10 | C23: Outubro | D23: 75 | E23: 100 | F23: =E23/D23 -> 1.3333333 | G23: =IF(F23>=I11,"Desempenho Ótimo",(IF(F23>H11,"Desempenho Bom",(IF(F23>J11,"Desempenho Médio",IF(F23<=J11,"Desempenho Deficitário",0)))))) -> #DIV/0! | H23: =H11 -> #DIV/0! | I23: =I11 -> #DIV/0! | J23: =J11 -> #DIV/0! | K23: 16700 | L23: ='Monitoramento Acumulado Geral'!Q23 -> 0 | M23: =(SUM(L14:L23))/K22 -> 0.68964072 | N23: =IF(M23>=P11,"Desempenho Ótimo",(IF(M23>O11,"Desempenho Bom",(IF(M23>Q11,"Desempenho Médio",IF(M23<=Q11,"Desempenho Deficitário",0)))))) -> #DIV/0! | O23: =O11 -> #DIV/0! | P23: =P11 -> #DIV/0! | Q23: =Q11 -> #DIV/0! | R23: 80 | S23: 100 | T23: =S23/R23 -> 1.25 | U23: =IF(T23>=W11,"Desempenho Ótimo",(IF(T23>V11,"Desempenho Bom",(IF(T23>X11,"Desempenho Médio",IF(T23<=X11,"Desempenho Deficitário",0)))))) -> #DIV/0! | V23: =V11 -> #DIV/0! | W23: =W11 -> #DIV/0! | X23: =X11 -> #DIV/0! | Y23: =Y11 -> #DIV/0! | Z23: =Z11 -> #DIV/0!
A24: Atena Consultoria Jr. | B24: =_xlfn.IFS(C24="Janeiro",1,C24="Fevereiro",2,C24="Março",3,C24="Abril",4,C24="Maio",5,C24="Junho",6,C24="Julho",7,C24="Agosto",8,C24="Setembro",9,C24="Outubro",10,C24="Novembro",11,C24="Dezembro",12,TRUE,0) -> 11 | C24: Novembro | D24: 75 | E24: 0 | F24: =E24/D24 -> 0 | G24: =IF(F24>=I12,"Desempenho Ótimo",(IF(F24>H12,"Desempenho Bom",(IF(F24>J12,"Desempenho Médio",IF(F24<=J12,"Desempenho Deficitário",0)))))) -> #DIV/0! | H24: =H12 -> #DIV/0! | I24: =I12 -> #DIV/0! | J24: =J12 -> #DIV/0! | K24: 16700 | L24: ='Monitoramento Acumulado Geral'!Q24 -> 0 | M24: =(SUM(L14:L24))/K23 -> 0.68964072 | N24: =IF(M24>=P12,"Desempenho Ótimo",(IF(M24>O12,"Desempenho Bom",(IF(M24>Q12,"Desempenho Médio",IF(M24<=Q12,"Desempenho Deficitário",0)))))) -> #DIV/0! | O24: =O12 -> #DIV/0! | P24: =P12 -> #DIV/0! | Q24: =Q12 -> #DIV/0! | R24: 80 | S24: 0 | T24: =S24/R24 -> 0 | U24: =IF(T24>=W12,"Desempenho Ótimo",(IF(T24>V12,"Desempenho Bom",(IF(T24>X12,"Desempenho Médio",IF(T24<=X12,"Desempenho Deficitário",0)))))) -> #DIV/0! | V24: =V12 -> #DIV/0! | W24: =W12 -> #DIV/0! | X24: =X12 -> #DIV/0! | Y24: =Y12 -> #DIV/0! | Z24: =Z12 -> #DIV/0!
A25: Atena Consultoria Jr. | B25: =_xlfn.IFS(C25="Janeiro",1,C25="Fevereiro",2,C25="Março",3,C25="Abril",4,C25="Maio",5,C25="Junho",6,C25="Julho",7,C25="Agosto",8,C25="Setembro",9,C25="Outubro",10,C25="Novembro",11,C25="Dezembro",12,TRUE,0) -> 12 | C25: Dezembro | D25: 75 | E25: 0 | F25: =E25/D25 -> 0 | G25: =IF(F25>=I13,"Desempenho Ótimo",(IF(F25>H13,"Desempenho Bom",(IF(F25>J13,"Desempenho Médio",IF(F25<=J13,"Desempenho Deficitário",0)))))) -> #DIV/0! | H25: =H13 -> #DIV/0! | I25: =I13 -> #DIV/0! | J25: =J13 -> #DIV/0! | K25: 16700 | L25: ='Monitoramento Acumulado Geral'!Q25 -> 0 | M25: =(SUM(L14:L25))/K24 -> 0.68964072 | N25: =IF(M25>=P13,"Desempenho Ótimo",(IF(M25>O13,"Desempenho Bom",(IF(M25>Q13,"Desempenho Médio",IF(M25<=Q13,"Desempenho Deficitário",0)))))) -> #DIV/0! | O25: =O13 -> #DIV/0! | P25: =P13 -> #DIV/0! | Q25: =Q13 -> #DIV/0! | R25: 80 | S25: 0 | T25: =S25/R25 -> 0 | U25: =IF(T25>=W13,"Desempenho Ótimo",(IF(T25>V13,"Desempenho Bom",(IF(T25>X13,"Desempenho Médio",IF(T25<=X13,"Desempenho Deficitário",0)))))) -> #DIV/0! | V25: =V13 -> #DIV/0! | W25: =W13 -> #DIV/0! | X25: =X13 -> #DIV/0! | Y25: =Y13 -> #DIV/0! | Z25: =Z13 -> #DIV/0!
A26: Atlântica Consultoria Internacional | B26: =_xlfn.IFS(C26="Janeiro",1,C26="Fevereiro",2,C26="Março",3,C26="Abril",4,C26="Maio",5,C26="Junho",6,C26="Julho",7,C26="Agosto",8,C26="Setembro",9,C26="Outubro",10,C26="Novembro",11,C26="Dezembro",12,TRUE,0) -> 1 | C26: Janeiro | D26: 55 | E26: 14 | F26: =E26/D26 -> 0.25454545 | G26: =IF(F26>=I14,"Desempenho Ótimo",(IF(F26>H14,"Desempenho Bom",(IF(F26>J14,"Desempenho Médio",IF(F26<=J14,"Desempenho Deficitário",0)))))) -> #DIV/0! | H26: =H14 -> #DIV/0! | I26: =I14 -> #DIV/0! | J26: =J14 -> #DIV/0! | K26: 2000 | L26: ='Monitoramento Acumulado Geral'!Q26 -> 244 | M26: =L26/K26 -> 0.122 | N26: =IF(M26>=P14,"Desempenho Ótimo",(IF(M26>O14,"Desempenho Bom",(IF(M26>Q14,"Desempenho Médio",IF(M26<=Q14,"Desempenho Deficitário",0)))))) -> #DIV/0! | O26: =O14 -> #DIV/0! | P26: =P14 -> #DIV/0! | Q26: =Q14 -> #DIV/0! | R26: 35 | S26: 0 | T26: =S26/R26 -> 0 | U26: =IF(T26>=W14,"Desempenho Ótimo",(IF(T26>V14,"Desempenho Bom",(IF(T26>X14,"Desempenho Médio",IF(T26<=X14,"Desempenho Deficitário",0)))))) -> #DIV/0! | V26: =V14 -> #DIV/0! | W26: =W14 -> #DIV/0! | X26: =X14 -> #DIV/0! | Y26: =Y14 -> #DIV/0! | Z26: =Z14 -> #DIV/0!
A27: Atlântica Consultoria Internacional | B27: =_xlfn.IFS(C27="Janeiro",1,C27="Fevereiro",2,C27="Março",3,C27="Abril",4,C27="Maio",5,C27="Junho",6,C27="Julho",7,C27="Agosto",8,C27="Setembro",9,C27="Outubro",10,C27="Novembro",11,C27="Dezembro",12,TRUE,0) -> 2 | C27: Fevereiro | D27: 55 | E27: 14 | F27: =E27/D27 -> 0.25454545 | G27: =IF(F27>=I15,"Desempenho Ótimo",(IF(F27>H15,"Desempenho Bom",(IF(F27>J15,"Desempenho Médio",IF(F27<=J15,"Desempenho Deficitário",0)))))) -> #DIV/0! | H27: =H15 -> #DIV/0! | I27: =I15 -> #DIV/0! | J27: =J15 -> #DIV/0! | K27: 2000 | L27: ='Monitoramento Acumulado Geral'!Q27 -> 0 | M27: =(SUM(L26:L27))/K26 -> 0.122 | N27: =IF(M27>=P15,"Desempenho Ótimo",(IF(M27>O15,"Desempenho Bom",(IF(M27>Q15,"Desempenho Médio",IF(M27<=Q15,"Desempenho Deficitário",0)))))) -> #DIV/0! | O27: =O15 -> #DIV/0! | P27: =P15 -> #DIV/0! | Q27: =Q15 -> #DIV/0! | R27: 35 | S27: 0 | T27: =S27/R27 -> 0 | U27: =IF(T27>=W15,"Desempenho Ótimo",(IF(T27>V15,"Desempenho Bom",(IF(T27>X15,"Desempenho Médio",IF(T27<=X15,"Desempenho Deficitário",0)))))) -> #DIV/0! | V27: =V15 -> #DIV/0! | W27: =W15 -> #DIV/0! | X27: =X15 -> #DIV/0! | Y27: =Y15 -> #DIV/0! | Z27: =Z15 -> #DIV/0!
A28: Atlântica Consultoria Internacional | B28: =_xlfn.IFS(C28="Janeiro",1,C28="Fevereiro",2,C28="Março",3,C28="Abril",4,C28="Maio",5,C28="Junho",6,C28="Julho",7,C28="Agosto",8,C28="Setembro",9,C28="Outubro",10,C28="Novembro",11,C28="Dezembro",12,TRUE,0) -> 3 | C28: Março | D28: 55 | E28: 14 | F28: =E28/D28 -> 0.25454545 | G28: =IF(F28>=I16,"Desempenho Ótimo",(IF(F28>H16,"Desempenho Bom",(IF(F28>J16,"Desempenho Médio",IF(F28<=J16,"Desempenho Deficitário",0)))))) -> #DIV/0! | H28: =H16 -> #DIV/0! | I28: =I16 -> #DIV/0! | J28: =J16 -> #DIV/0! | K28: 2000 | L28: ='Monitoramento Acumulado Geral'!Q28 -> 0 | M28: =(SUM(L26:L28))/K27 -> 0.122 | N28: =IF(M28>=P16,"Desempenho Ótimo",(IF(M28>O16,"Desempenho Bom",(IF(M28>Q16,"Desempenho Médio",IF(M28<=Q16,"Desempenho Deficitário",0)))))) -> #DIV/0! | O28: =O16 -> #DIV/0! | P28: =P16 -> #DIV/0! | Q28: =Q16 -> #DIV/0! | R28: 35 | S28: 0 | T28: =S28/R28 -> 0 | U28: =IF(T28>=W16,"Desempenho Ótimo",(IF(T28>V16,"Desempenho Bom",(IF(T28>X16,"Desempenho Médio",IF(T28<=X16,"Desempenho Deficitário",0)))))) -> #DIV/0! | V28: =V16 -> #DIV/0! | W28: =W16 -> #DIV/0! | X28: =X16 -> #DIV/0! | Y28: =Y16 -> #DIV/0! | Z28: =Z16 -> #DIV/0!
A29: Atlântica Consultoria Internacional | B29: =_xlfn.IFS(C29="Janeiro",1,C29="Fevereiro",2,C29="Março",3,C29="Abril",4,C29="Maio",5,C29="Junho",6,C29="Julho",7,C29="Agosto",8,C29="Setembro",9,C29="Outubro",10,C29="Novembro",11,C29="Dezembro",12,TRUE,0) -> 4 | C29: Abril | D29: 55 | E29: 28 | F29: =E29/D29 -> 0.50909091 | G29: =IF(F29>=I17,"Desempenho Ótimo",(IF(F29>H17,"Desempenho Bom",(IF(F29>J17,"Desempenho Médio",IF(F29<=J17,"Desempenho Deficitário",0)))))) -> #DIV/0! | H29: =H17 -> #DIV/0! | I29: =I17 -> #DIV/0! | J29: =J17 -> #DIV/0! | K29: 2000 | L29: ='Monitoramento Acumulado Geral'!Q29 -> 122 | M29: =(SUM(L26:L29))/K28 -> 0.183 | N29: =IF(M29>=P17,"Desempenho Ótimo",(IF(M29>O17,"Desempenho Bom",(IF(M29>Q17,"Desempenho Médio",IF(M29<=Q17,"Desempenho Deficitário",0)))))) -> #DIV/0! | O29: =O17 -> #DIV/0! | P29: =P17 -> #DIV/0! | Q29: =Q17 -> #DIV/0! | R29: 35 | S29: 0 | T29: =S29/R29 -> 0 | U29: =IF(T29>=W17,"Desempenho Ótimo",(IF(T29>V17,"Desempenho Bom",(IF(T29>X17,"Desempenho Médio",IF(T29<=X17,"Desempenho Deficitário",0)))))) -> #DIV/0! | V29: =V17 -> #DIV/0! | W29: =W17 -> #DIV/0! | X29: =X17 -> #DIV/0! | Y29: =Y17 -> #DIV/0! | Z29: =Z17 -> #DIV/0!
A30: Atlântica Consultoria Internacional | B30: =_xlfn.IFS(C30="Janeiro",1,C30="Fevereiro",2,C30="Março",3,C30="Abril",4,C30="Maio",5,C30="Junho",6,C30="Julho",7,C30="Agosto",8,C30="Setembro",9,C30="Outubro",10,C30="Novembro",11,C30="Dezembro",12,TRUE,0) -> 5 | C30: Maio | D30: 55 | E30: 28 | F30: =E30/D30 -> 0.50909091 | G30: =IF(F30>=I18,"Desempenho Ótimo",(IF(F30>H18,"Desempenho Bom",(IF(F30>J18,"Desempenho Médio",IF(F30<=J18,"Desempenho Deficitário",0)))))) -> #DIV/0! | H30: =H18 -> #DIV/0! | I30: =I18 -> #DIV/0! | J30: =J18 -> #DIV/0! | K30: 2000 | L30: ='Monitoramento Acumulado Geral'!Q30 -> 0 | M30: =(SUM(L26:L30))/K29 -> 0.183 | N30: =IF(M30>=P18,"Desempenho Ótimo",(IF(M30>O18,"Desempenho Bom",(IF(M30>Q18,"Desempenho Médio",IF(M30<=Q18,"Desempenho Deficitário",0)))))) -> #DIV/0! | O30: =O18 -> #DIV/0! | P30: =P18 -> #DIV/0! | Q30: =Q18 -> #DIV/0! | R30: 35 | S30: 21 | T30: =S30/R30 -> 0.6 | U30: =IF(T30>=W18,"Desempenho Ótimo",(IF(T30>V18,"Desempenho Bom",(IF(T30>X18,"Desempenho Médio",IF(T30<=X18,"Desempenho Deficitário",0)))))) -> #DIV/0! | V30: =V18 -> #DIV/0! | W30: =W18 -> #DIV/0! | X30: =X18 -> #DIV/0! | Y30: =Y18 -> #DIV/0! | Z30: =Z18 -> #DIV/0!
A31: Atlântica Consultoria Internacional | B31: =_xlfn.IFS(C31="Janeiro",1,C31="Fevereiro",2,C31="Março",3,C31="Abril",4,C31="Maio",5,C31="Junho",6,C31="Julho",7,C31="Agosto",8,C31="Setembro",9,C31="Outubro",10,C31="Novembro",11,C31="Dezembro",12,TRUE,0) -> 6 | C31: Junho | D31: 55 | E31: 43 | F31: =E31/D31 -> 0.78181818 | G31: =IF(F31>=I19,"Desempenho Ótimo",(IF(F31>H19,"Desempenho Bom",(IF(F31>J19,"Desempenho Médio",IF(F31<=J19,"Desempenho Deficitário",0)))))) -> #DIV/0! | H31: =H19 -> #DIV/0! | I31: =I19 -> #DIV/0! | J31: =J19 -> #DIV/0! | K31: 2000 | L31: ='Monitoramento Acumulado Geral'!Q31 -> 1 | M31: =(SUM(L26:L31))/K30 -> 0.1835 | N31: =IF(M31>=P19,"Desempenho Ótimo",(IF(M31>O19,"Desempenho Bom",(IF(M31>Q19,"Desempenho Médio",IF(M31<=Q19,"Desempenho Deficitário",0)))))) -> #DIV/0! | O31: =O19 -> #DIV/0! | P31: =P19 -> #DIV/0! | Q31: =Q19 -> #DIV/0! | R31: 35 | S31: 21 | T31: =S31/R31 -> 0.6 | U31: =IF(T31>=W19,"Desempenho Ótimo",(IF(T31>V19,"Desempenho Bom",(IF(T31>X19,"Desempenho Médio",IF(T31<=X19,"Desempenho Deficitário",0)))))) -> #DIV/0! | V31: =V19 -> #DIV/0! | W31: =W19 -> #DIV/0! | X31: =X19 -> #DIV/0! | Y31: =Y19 -> #DIV/0! | Z31: =Z19 -> #DIV/0!
A32: Atlântica Consultoria Internacional | B32: =_xlfn.IFS(C32="Janeiro",1,C32="Fevereiro",2,C32="Março",3,C32="Abril",4,C32="Maio",5,C32="Junho",6,C32="Julho",7,C32="Agosto",8,C32="Setembro",9,C32="Outubro",10,C32="Novembro",11,C32="Dezembro",12,TRUE,0) -> 7 | C32: Julho | D32: 55 | E32: 43 | F32: =E32/D32 -> 0.78181818 | G32: =IF(F32>=I20,"Desempenho Ótimo",(IF(F32>H20,"Desempenho Bom",(IF(F32>J20,"Desempenho Médio",IF(F32<=J20,"Desempenho Deficitário",0)))))) -> #DIV/0! | H32: =H20 -> #DIV/0! | I32: =I20 -> #DIV/0! | J32: =J20 -> #DIV/0! | K32: 2000 | L32: ='Monitoramento Acumulado Geral'!Q32 -> 0 | M32: =(SUM(L26:L32))/K31 -> 0.1835 | N32: =IF(M32>=P20,"Desempenho Ótimo",(IF(M32>O20,"Desempenho Bom",(IF(M32>Q20,"Desempenho Médio",IF(M32<=Q20,"Desempenho Deficitário",0)))))) -> #DIV/0! | O32: =O20 -> #DIV/0! | P32: =P20 -> #DIV/0! | Q32: =Q20 -> #DIV/0! | R32: 35 | S32: 21 | T32: =S32/R32 -> 0.6 | U32: =IF(T32>=W20,"Desempenho Ótimo",(IF(T32>V20,"Desempenho Bom",(IF(T32>X20,"Desempenho Médio",IF(T32<=X20,"Desempenho Deficitário",0)))))) -> #DIV/0! | V32: =V20 -> #DIV/0! | W32: =W20 -> #DIV/0! | X32: =X20 -> #DIV/0! | Y32: =Y20 -> #DIV/0! | Z32: =Z20 -> #DIV/0!
A33: Atlântica Consultoria Internacional | B33: =_xlfn.IFS(C33="Janeiro",1,C33="Fevereiro",2,C33="Março",3,C33="Abril",4,C33="Maio",5,C33="Junho",6,C33="Julho",7,C33="Agosto",8,C33="Setembro",9,C33="Outubro",10,C33="Novembro",11,C33="Dezembro",12,TRUE,0) -> 8 | C33: Agosto | D33: 55 | E33: 43 | F33: =E33/D33 -> 0.78181818 | G33: =IF(F33>=I21,"Desempenho Ótimo",(IF(F33>H21,"Desempenho Bom",(IF(F33>J21,"Desempenho Médio",IF(F33<=J21,"Desempenho Deficitário",0)))))) -> #DIV/0! | H33: =H21 -> #DIV/0! | I33: =I21 -> #DIV/0! | J33: =J21 -> #DIV/0! | K33: 2000 | L33: ='Monitoramento Acumulado Geral'!Q33 -> 0 | M33: =(SUM(L26:L33))/K32 -> 0.1835 | N33: =IF(M33>=P21,"Desempenho Ótimo",(IF(M33>O21,"Desempenho Bom",(IF(M33>Q21,"Desempenho Médio",IF(M33<=Q21,"Desempenho Deficitário",0)))))) -> #DIV/0! | O33: =O21 -> #DIV/0! | P33: =P21 -> #DIV/0! | Q33: =Q21 -> #DIV/0! | R33: 35 | S33: 21 | T33: =S33/R33 -> 0.6 | U33: =IF(T33>=W21,"Desempenho Ótimo",(IF(T33>V21,"Desempenho Bom",(IF(T33>X21,"Desempenho Médio",IF(T33<=X21,"Desempenho Deficitário",0)))))) -> #DIV/0! | V33: =V21 -> #DIV/0! | W33: =W21 -> #DIV/0! | X33: =X21 -> #DIV/0! | Y33: =Y21 -> #DIV/0! | Z33: =Z21 -> #DIV/0!
A34: Atlântica Consultoria Internacional | B34: =_xlfn.IFS(C34="Janeiro",1,C34="Fevereiro",2,C34="Março",3,C34="Abril",4,C34="Maio",5,C34="Junho",6,C34="Julho",7,C34="Agosto",8,C34="Setembro",9,C34="Outubro",10,C34="Novembro",11,C34="Dezembro",12,TRUE,0) -> 9 | C34: Setembro | D34: 55 | E34: 56 | F34: =E34/D34 -> 1.0181818 | G34: =IF(F34>=I22,"Desempenho Ótimo",(IF(F34>H22,"Desempenho Bom",(IF(F34>J22,"Desempenho Médio",IF(F34<=J22,"Desempenho Deficitário",0)))))) -> #DIV/0! | H34: =H22 -> #DIV/0! | I34: =I22 -> #DIV/0! | J34: =J22 -> #DIV/0! | K34: 2000 | L34: ='Monitoramento Acumulado Geral'!Q34 -> 3900 | M34: =(SUM(L26:L34))/K33 -> 2.1335 | N34: =IF(M34>=P22,"Desempenho Ótimo",(IF(M34>O22,"Desempenho Bom",(IF(M34>Q22,"Desempenho Médio",IF(M34<=Q22,"Desempenho Deficitário",0)))))) -> #DIV/0! | O34: =O22 -> #DIV/0! | P34: =P22 -> #DIV/0! | Q34: =Q22 -> #DIV/0! | R34: 35 | S34: 21 | T34: =S34/R34 -> 0.6 | U34: =IF(T34>=W22,"Desempenho Ótimo",(IF(T34>V22,"Desempenho Bom",(IF(T34>X22,"Desempenho Médio",IF(T34<=X22,"Desempenho Deficitário",0)))))) -> #DIV/0! | V34: =V22 -> #DIV/0! | W34: =W22 -> #DIV/0! | X34: =X22 -> #DIV/0! | Y34: =Y22 -> #DIV/0! | Z34: =Z22 -> #DIV/0!
A35: Atlântica Consultoria Internacional | B35: =_xlfn.IFS(C35="Janeiro",1,C35="Fevereiro",2,C35="Março",3,C35="Abril",4,C35="Maio",5,C35="Junho",6,C35="Julho",7,C35="Agosto",8,C35="Setembro",9,C35="Outubro",10,C35="Novembro",11,C35="Dezembro",12,TRUE,0) -> 10 | C35: Outubro | D35: 55 | E35: 56 | F35: =E35/D35 -> 1.0181818 | G35: =IF(F35>=I23,"Desempenho Ótimo",(IF(F35>H23,"Desempenho Bom",(IF(F35>J23,"Desempenho Médio",IF(F35<=J23,"Desempenho Deficitário",0)))))) -> #DIV/0! | H35: =H23 -> #DIV/0! | I35: =I23 -> #DIV/0! | J35: =J23 -> #DIV/0! | K35: 2000 | L35: ='Monitoramento Acumulado Geral'!Q35 -> 0 | M35: =(SUM(L26:L35))/K34 -> 2.1335 | N35: =IF(M35>=P23,"Desempenho Ótimo",(IF(M35>O23,"Desempenho Bom",(IF(M35>Q23,"Desempenho Médio",IF(M35<=Q23,"Desempenho Deficitário",0)))))) -> #DIV/0! | O35: =O23 -> #DIV/0! | P35: =P23 -> #DIV/0! | Q35: =Q23 -> #DIV/0! | R35: 35 | S35: 21 | T35: =S35/R35 -> 0.6 | U35: =IF(T35>=W23,"Desempenho Ótimo",(IF(T35>V23,"Desempenho Bom",(IF(T35>X23,"Desempenho Médio",IF(T35<=X23,"Desempenho Deficitário",0)))))) -> #DIV/0! | V35: =V23 -> #DIV/0! | W35: =W23 -> #DIV/0! | X35: =X23 -> #DIV/0! | Y35: =Y23 -> #DIV/0! | Z35: =Z23 -> #DIV/0!
A36: Atlântica Consultoria Internacional | B36: =_xlfn.IFS(C36="Janeiro",1,C36="Fevereiro",2,C36="Março",3,C36="Abril",4,C36="Maio",5,C36="Junho",6,C36="Julho",7,C36="Agosto",8,C36="Setembro",9,C36="Outubro",10,C36="Novembro",11,C36="Dezembro",12,TRUE,0) -> 11 | C36: Novembro | D36: 55 | E36: 0 | F36: =E36/D36 -> 0 | G36: =IF(F36>=I24,"Desempenho Ótimo",(IF(F36>H24,"Desempenho Bom",(IF(F36>J24,"Desempenho Médio",IF(F36<=J24,"Desempenho Deficitário",0)))))) -> #DIV/0! | H36: =H24 -> #DIV/0! | I36: =I24 -> #DIV/0! | J36: =J24 -> #DIV/0! | K36: 2000 | L36: ='Monitoramento Acumulado Geral'!Q36 -> 0 | M36: =(SUM(L26:L36))/K35 -> 2.1335 | N36: =IF(M36>=P24,"Desempenho Ótimo",(IF(M36>O24,"Desempenho Bom",(IF(M36>Q24,"Desempenho Médio",IF(M36<=Q24,"Desempenho Deficitário",0)))))) -> #DIV/0! | O36: =O24 -> #DIV/0! | P36: =P24 -> #DIV/0! | Q36: =Q24 -> #DIV/0! | R36: 35 | S36: 0 | T36: =S36/R36 -> 0 | U36: =IF(T36>=W24,"Desempenho Ótimo",(IF(T36>V24,"Desempenho Bom",(IF(T36>X24,"Desempenho Médio",IF(T36<=X24,"Desempenho Deficitário",0)))))) -> #DIV/0! | V36: =V24 -> #DIV/0! | W36: =W24 -> #DIV/0! | X36: =X24 -> #DIV/0! | Y36: =Y24 -> #DIV/0! | Z36: =Z24 -> #DIV/0!
A37: Atlântica Consultoria Internacional | B37: =_xlfn.IFS(C37="Janeiro",1,C37="Fevereiro",2,C37="Março",3,C37="Abril",4,C37="Maio",5,C37="Junho",6,C37="Julho",7,C37="Agosto",8,C37="Setembro",9,C37="Outubro",10,C37="Novembro",11,C37="Dezembro",12,TRUE,0) -> 12 | C37: Dezembro | D37: 55 | E37: 0 | F37: =E37/D37 -> 0 | G37: =IF(F37>=I25,"Desempenho Ótimo",(IF(F37>H25,"Desempenho Bom",(IF(F37>J25,"Desempenho Médio",IF(F37<=J25,"Desempenho Deficitário",0)))))) -> #DIV/0! | H37: =H25 -> #DIV/0! | I37: =I25 -> #DIV/0! | J37: =J25 -> #DIV/0! | K37: 2000 | L37: ='Monitoramento Acumulado Geral'!Q37 -> 0 | M37: =(SUM(L27:L37))/K36 -> 2.0115 | N37: =IF(M37>=P25,"Desempenho Ótimo",(IF(M37>O25,"Desempenho Bom",(IF(M37>Q25,"Desempenho Médio",IF(M37<=Q25,"Desempenho Deficitário",0)))))) -> #DIV/0! | O37: =O25 -> #DIV/0! | P37: =P25 -> #DIV/0! | Q37: =Q25 -> #DIV/0! | R37: 35 | S37: 0 | T37: =S37/R37 -> 0 | U37: =IF(T37>=W25,"Desempenho Ótimo",(IF(T37>V25,"Desempenho Bom",(IF(T37>X25,"Desempenho Médio",IF(T37<=X25,"Desempenho Deficitário",0)))))) -> #DIV/0! | V37: =V25 -> #DIV/0! | W37: =W25 -> #DIV/0! | X37: =X25 -> #DIV/0! | Y37: =Y25 -> #DIV/0! | Z37: =Z25 -> #DIV/0!
A38: Automatiza Júnior | B38: =_xlfn.IFS(C38="Janeiro",1,C38="Fevereiro",2,C38="Março",3,C38="Abril",4,C38="Maio",5,C38="Junho",6,C38="Julho",7,C38="Agosto",8,C38="Setembro",9,C38="Outubro",10,C38="Novembro",11,C38="Dezembro",12,TRUE,0) -> 1 | C38: Janeiro | D38: 75 | E38: 0 | F38: =E38/D38 -> 0 | G38: =IF(F38>=I26,"Desempenho Ótimo",(IF(F38>H26,"Desempenho Bom",(IF(F38>J26,"Desempenho Médio",IF(F38<=J26,"Desempenho Deficitário",0)))))) -> #DIV/0! | H38: =H26 -> #DIV/0! | I38: =I26 -> #DIV/0! | J38: =J26 -> #DIV/0! | K38: 19817.25 | L38: ='Monitoramento Acumulado Geral'!Q38 -> 0 | M38: =L38/K38 -> 0 | N38: =IF(M38>=P26,"Desempenho Ótimo",(IF(M38>O26,"Desempenho Bom",(IF(M38>Q26,"Desempenho Médio",IF(M38<=Q26,"Desempenho Deficitário",0)))))) -> #DIV/0! | O38: =O26 -> #DIV/0! | P38: =P26 -> #DIV/0! | Q38: =Q26 -> #DIV/0! | R38: 80 | S38: 11 | T38: =S38/R38 -> 0.1375 | U38: =IF(T38>=W26,"Desempenho Ótimo",(IF(T38>V26,"Desempenho Bom",(IF(T38>X26,"Desempenho Médio",IF(T38<=X26,"Desempenho Deficitário",0)))))) -> #DIV/0! | V38: =V26 -> #DIV/0! | W38: =W26 -> #DIV/0! | X38: =X26 -> #DIV/0! | Y38: =Y26 -> #DIV/0! | Z38: =Z26 -> #DIV/0!
A39: Automatiza Júnior | B39: =_xlfn.IFS(C39="Janeiro",1,C39="Fevereiro",2,C39="Março",3,C39="Abril",4,C39="Maio",5,C39="Junho",6,C39="Julho",7,C39="Agosto",8,C39="Setembro",9,C39="Outubro",10,C39="Novembro",11,C39="Dezembro",12,TRUE,0) -> 2 | C39: Fevereiro | D39: 75 | E39: 11 | F39: =E39/D39 -> 0.14666667 | G39: =IF(F39>=I27,"Desempenho Ótimo",(IF(F39>H27,"Desempenho Bom",(IF(F39>J27,"Desempenho Médio",IF(F39<=J27,"Desempenho Deficitário",0)))))) -> #DIV/0! | H39: =H27 -> #DIV/0! | I39: =I27 -> #DIV/0! | J39: =J27 -> #DIV/0! | K39: 19817.25 | L39: ='Monitoramento Acumulado Geral'!Q39 -> 900 | M39: =(SUM(L38:L39))/K38 -> 0.045414979 | N39: =IF(M39>=P27,"Desempenho Ótimo",(IF(M39>O27,"Desempenho Bom",(IF(M39>Q27,"Desempenho Médio",IF(M39<=Q27,"Desempenho Deficitário",0)))))) -> #DIV/0! | O39: =O27 -> #DIV/0! | P39: =P27 -> #DIV/0! | Q39: =Q27 -> #DIV/0! | R39: 80 | S39: 11 | T39: =S39/R39 -> 0.1375 | U39: =IF(T39>=W27,"Desempenho Ótimo",(IF(T39>V27,"Desempenho Bom",(IF(T39>X27,"Desempenho Médio",IF(T39<=X27,"Desempenho Deficitário",0)))))) -> #DIV/0! | V39: =V27 -> #DIV/0! | W39: =W27 -> #DIV/0! | X39: =X27 -> #DIV/0! | Y39: =Y27 -> #DIV/0! | Z39: =Z27 -> #DIV/0!
A40: Automatiza Júnior | B40: =_xlfn.IFS(C40="Janeiro",1,C40="Fevereiro",2,C40="Março",3,C40="Abril",4,C40="Maio",5,C40="Junho",6,C40="Julho",7,C40="Agosto",8,C40="Setembro",9,C40="Outubro",10,C40="Novembro",11,C40="Dezembro",12,TRUE,0) -> 3 | C40: Março | D40: 75 | E40: 26 | F40: =E40/D40 -> 0.34666667 | G40: =IF(F40>=I28,"Desempenho Ótimo",(IF(F40>H28,"Desempenho Bom",(IF(F40>J28,"Desempenho Médio",IF(F40<=J28,"Desempenho Deficitário",0)))))) -> #DIV/0! | H40: =H28 -> #DIV/0! | I40: =I28 -> #DIV/0! | J40: =J28 -> #DIV/0! | K40: 19817.25 | L40: ='Monitoramento Acumulado Geral'!Q40 -> 3464.08 | M40: =(SUM(L38:L40))/K39 -> 0.22021623 | N40: =IF(M40>=P28,"Desempenho Ótimo",(IF(M40>O28,"Desempenho Bom",(IF(M40>Q28,"Desempenho Médio",IF(M40<=Q28,"Desempenho Deficitário",0)))))) -> #DIV/0! | O40: =O28 -> #DIV/0! | P40: =P28 -> #DIV/0! | Q40: =Q28 -> #DIV/0! | R40: 80 | S40: 11 | T40: =S40/R40 -> 0.1375 | U40: =IF(T40>=W28,"Desempenho Ótimo",(IF(T40>V28,"Desempenho Bom",(IF(T40>X28,"Desempenho Médio",IF(T40<=X28,"Desempenho Deficitário",0)))))) -> #DIV/0! | V40: =V28 -> #DIV/0! | W40: =W28 -> #DIV/0! | X40: =X28 -> #DIV/0! | Y40: =Y28 -> #DIV/0! | Z40: =Z28 -> #DIV/0!
...

Sheet Cálculo Banda Part. Event.
